Script started on 2025-08-21 02:40:21-04:00 [COMMAND="set -x && PYTHONPATH=. pytest tests/" TERM="screen.xterm-256color" TTY="/dev/pty5" COLUMNS="121" LINES="40"]
+ PYTHONPATH=.
+ pytest tests/
Please ensure psutil_cygwin is installed
INTERNALERROR> Traceback (most recent call last):
INTERNALERROR>   File "/home/phdyex/my-repos/psutil-cygwin/tests/test_psutil_cygwin.py", line 13, in <module>
INTERNALERROR>     import psutil_cygwin as psutil
INTERNALERROR>   File "/home/phdyex/my-repos/psutil-cygwin/psutil_cygwin/__init__.py", line 24, in <module>
INTERNALERROR>     from .core import (
INTERNALERROR> ImportError: cannot import name 'User' from 'psutil_cygwin.core' (/home/phdyex/my-repos/psutil-cygwin/psutil_cygwin/core.py)
INTERNALERROR> 
INTERNALERROR> During handling of the above exception, another exception occurred:
INTERNALERROR> 
INTERNALERROR> Traceback (most recent call last):
INTERNALERROR>   File "/usr/local/lib/python3.9/site-packages/_pytest/main.py", line 283, in wrap_session
INTERNALERROR>     session.exitstatus = doit(config, session) or 0
INTERNALERROR>   File "/usr/local/lib/python3.9/site-packages/_pytest/main.py", line 336, in _main
INTERNALERROR>     config.hook.pytest_collection(session=session)
INTERNALERROR>   File "/usr/local/lib/python3.9/site-packages/pluggy/_hooks.py", line 513, in __call__
INTERNALERROR>     return self._hookexec(self.name, self._hookimpls.copy(), kwargs, firstresult)
INTERNALERROR>   File "/usr/local/lib/python3.9/site-packages/pluggy/_manager.py", line 120, in _hookexec
INTERNALERROR>     return self._inner_hookexec(hook_name, methods, kwargs, firstresult)
INTERNALERROR>   File "/usr/local/lib/python3.9/site-packages/pluggy/_callers.py", line 139, in _multicall
INTERNALERROR>     raise exception.with_traceback(exception.__traceback__)
INTERNALERROR>   File "/usr/local/lib/python3.9/site-packages/pluggy/_callers.py", line 122, in _multicall
INTERNALERROR>     teardown.throw(exception)  # type: ignore[union-attr]
INTERNALERROR>   File "/usr/local/lib/python3.9/site-packages/_pytest/logging.py", line 790, in pytest_collection
INTERNALERROR>     return (yield)
INTERNALERROR>   File "/usr/local/lib/python3.9/site-packages/pluggy/_callers.py", line 122, in _multicall
INTERNALERROR>     teardown.throw(exception)  # type: ignore[union-attr]
INTERNALERROR>   File "/usr/local/lib/python3.9/site-packages/_pytest/warnings.py", line 121, in pytest_collection
INTERNALERROR>     return (yield)
INTERNALERROR>   File "/usr/local/lib/python3.9/site-packages/pluggy/_callers.py", line 122, in _multicall
INTERNALERROR>     teardown.throw(exception)  # type: ignore[union-attr]
INTERNALERROR>   File "/usr/local/lib/python3.9/site-packages/_pytest/config/__init__.py", line 1417, in pytest_collection
INTERNALERROR>     return (yield)
INTERNALERROR>   File "/usr/local/lib/python3.9/site-packages/pluggy/_callers.py", line 103, in _multicall
INTERNALERROR>     res = hook_impl.function(*args)
INTERNALERROR>   File "/usr/local/lib/python3.9/site-packages/_pytest/main.py", line 347, in pytest_collection
INTERNALERROR>     session.perform_collect()
INTERNALERROR>   File "/usr/local/lib/python3.9/site-packages/_pytest/main.py", line 809, in perform_collect
INTERNALERROR>     self.items.extend(self.genitems(node))
INTERNALERROR>   File "/usr/local/lib/python3.9/site-packages/_pytest/main.py", line 975, in genitems
INTERNALERROR>     yield from self.genitems(subnode)
INTERNALERROR>   File "/usr/local/lib/python3.9/site-packages/_pytest/main.py", line 970, in genitems
INTERNALERROR>     rep, duplicate = self._collect_one_node(node, handle_dupes)
INTERNALERROR>   File "/usr/local/lib/python3.9/site-packages/_pytest/main.py", line 835, in _collect_one_node
INTERNALERROR>     rep = collect_one_node(node)
INTERNALERROR>   File "/usr/local/lib/python3.9/site-packages/_pytest/runner.py", line 567, in collect_one_node
INTERNALERROR>     rep: CollectReport = ihook.pytest_make_collect_report(collector=collector)
INTERNALERROR>   File "/usr/local/lib/python3.9/site-packages/pluggy/_hooks.py", line 513, in __call__
INTERNALERROR>     return self._hookexec(self.name, self._hookimpls.copy(), kwargs, firstresult)
INTERNALERROR>   File "/usr/local/lib/python3.9/site-packages/pluggy/_manager.py", line 120, in _hookexec
INTERNALERROR>     return self._inner_hookexec(hook_name, methods, kwargs, firstresult)
INTERNALERROR>   File "/usr/local/lib/python3.9/site-packages/pluggy/_callers.py", line 139, in _multicall
INTERNALERROR>     raise exception.with_traceback(exception.__traceback__)
INTERNALERROR>   File "/usr/local/lib/python3.9/site-packages/pluggy/_callers.py", line 122, in _multicall
INTERNALERROR>     teardown.throw(exception)  # type: ignore[union-attr]
INTERNALERROR>   File "/usr/local/lib/python3.9/site-packages/_pytest/capture.py", line 860, in pytest_make_collect_report
INTERNALERROR>     rep = yield
INTERNALERROR>   File "/usr/local/lib/python3.9/site-packages/pluggy/_callers.py", line 103, in _multicall
INTERNALERROR>     res = hook_impl.function(*args)
INTERNALERROR>   File "/usr/local/lib/python3.9/site-packages/_pytest/runner.py", line 391, in pytest_make_collect_report
INTERNALERROR>     call = CallInfo.from_call(
INTERNALERROR>   File "/usr/local/lib/python3.9/site-packages/_pytest/runner.py", line 341, in from_call
INTERNALERROR>     result: TResult | None = func()
INTERNALERROR>   File "/usr/local/lib/python3.9/site-packages/_pytest/runner.py", line 389, in collect
INTERNALERROR>     return list(collector.collect())
INTERNALERROR>   File "/usr/local/lib/python3.9/site-packages/_pytest/python.py", line 549, in collect
INTERNALERROR>     self._register_setup_module_fixture()
INTERNALERROR>   File "/usr/local/lib/python3.9/site-packages/_pytest/python.py", line 562, in _register_setup_module_fixture
INTERNALERROR>     self.obj, ("setUpModule", "setup_module")
INTERNALERROR>   File "/usr/local/lib/python3.9/site-packages/_pytest/python.py", line 284, in obj
INTERNALERROR>     self._obj = obj = self._getobj()
INTERNALERROR>   File "/usr/local/lib/python3.9/site-packages/_pytest/python.py", line 546, in _getobj
INTERNALERROR>     return importtestmodule(self.path, self.config)
INTERNALERROR>   File "/usr/local/lib/python3.9/site-packages/_pytest/python.py", line 493, in importtestmodule
INTERNALERROR>     mod = import_path(
INTERNALERROR>   File "/usr/local/lib/python3.9/site-packages/_pytest/pathlib.py", line 582, in import_path
INTERNALERROR>     importlib.import_module(module_name)
INTERNALERROR>   File "/usr/lib/python3.9/importlib/__init__.py", line 127, in import_module
INTERNALERROR>     return _bootstrap._gcd_import(name[level:], package, level)
INTERNALERROR>   File "<frozen importlib._bootstrap>", line 1030, in _gcd_import
INTERNALERROR>   File "<frozen importlib._bootstrap>", line 1007, in _find_and_load
INTERNALERROR>   File "<frozen importlib._bootstrap>", line 986, in _find_and_load_unlocked
INTERNALERROR>   File "<frozen importlib._bootstrap>", line 680, in _load_unlocked
INTERNALERROR>   File "/usr/local/lib/python3.9/site-packages/_pytest/assertion/rewrite.py", line 184, in exec_module
INTERNALERROR>     exec(co, module.__dict__)
INTERNALERROR>   File "/home/phdyex/my-repos/psutil-cygwin/tests/test_psutil_cygwin.py", line 16, in <module>
INTERNALERROR>     sys.exit(1)
INTERNALERROR> SystemExit: 1
mainloop: caught unexpected SystemExit!
1 error in 0.13s
Script done on 2025-08-21 02:40:22-04:00 [COMMAND_EXIT_CODE="3"]

